<?xml version="1.0" encoding="utf-8"?>
<!-- =================================================================================== -->
<!-- |    This document was autogenerated by xacro from robot.urdf.xacro               | -->
<!-- |    EDITING THIS FILE BY HAND IS NOT RECOMMENDED                                 | -->
<!-- =================================================================================== -->
<robot name="SimpleMouse">
  <link name="base_link"/>
  <link name="body">
    <visual>
      <geometry>
        <box size="0.07 0.13 0.055"/>
      </geometry>
    </visual>
    <collision>
      <geometry>
        <box size="0.07 0.13 0.055"/>
      </geometry>
    </collision>
    <inertial>
      <origin rpy="0 0 0" xyz="0 0 0"/>
      <mass value="1.68"/>
      <inertia ixx="0.0027895" ixy="0" ixz="0" iyx="0" iyy="0.0011095" iyz="0" izx="0" izy="0" izz="0.003052"/>
    </inertial>
  </link>
  <joint name="body_joint" type="fixed">
    <parent link="base_link"/>
    <child link="body"/>
    <origin rpy="0 0 0" xyz="0 0 0.0275"/>
  </joint>
  <gazebo>
    <plugin filename="libgazebo_ros_diff_drive.so" name="differential_drive_controller">
      <leftJoint>wheel_l_joint</leftJoint>
      <rightJoint>wheel_r_joint</rightJoint>
      <robotBaseFrame>base_link</robotBaseFrame>
      <wheelSeparation>0.08</wheelSeparation>
      <wheelDiameter>0.048</wheelDiameter>
      <publishWheelJointState>true</publishWheelJointState>
      <legacyMode>false</legacyMode>
      <odometryTopic>odometry</odometryTopic>
      <odometryFrame>odometry</odometryFrame>
    </plugin>
  </gazebo>
  <link name="wheel_r">
    <visual>
      <geometry>
        <cylinder length="0.008" radius="0.024"/>
      </geometry>
    </visual>
    <collision>
      <geometry>
        <cylinder length="0.008" radius="0.024"/>
      </geometry>
    </collision>
    <inertial>
      <origin rpy="0 0 0" xyz="0 0 0"/>
      <mass value="0.112"/>
      <inertia ixx="1.67253333333e-05" ixy="0" ixz="0" iyx="0" iyy="1.67253333333e-05" iyz="0" izx="0" izy="0" izz="3.2256e-05"/>
    </inertial>
  </link>
  <joint name="wheel_r_joint" type="continuous">
    <parent link="body"/>
    <child link="wheel_r"/>
    <origin rpy="0 1.57079632679 0" xyz="0.04 0 -0.0055"/>
    <axis xyz="0 0 -1"/>
    <limit effort="10" velocity="10"/>
    <joint_properties damping="0.0" friction="0.0"/>
  </joint>
  <link name="wheel_l">
    <visual>
      <geometry>
        <cylinder length="0.008" radius="0.024"/>
      </geometry>
    </visual>
    <collision>
      <geometry>
        <cylinder length="0.008" radius="0.024"/>
      </geometry>
    </collision>
    <inertial>
      <origin rpy="0 0 0" xyz="0 0 0"/>
      <mass value="0.112"/>
      <inertia ixx="1.67253333333e-05" ixy="0" ixz="0" iyx="0" iyy="1.67253333333e-05" iyz="0" izx="0" izy="0" izz="3.2256e-05"/>
    </inertial>
  </link>
  <joint name="wheel_l_joint" type="continuous">
    <parent link="body"/>
    <child link="wheel_l"/>
    <origin rpy="0 1.57079632679 0" xyz="-0.04 0 -0.0055"/>
    <axis xyz="0 0 -1"/>
    <limit effort="10" velocity="10"/>
    <joint_properties damping="0.0" friction="0.0"/>
  </joint>
  <link name="front_sensor">
    <visual>
      <geometry>
        <box size="0.01 0.005 0.005"/>
      </geometry>
    </visual>
    <inertial>
      <mass value="0.0001"/>
      <inertia ixx="0.0001" ixy="0" ixz="0" iyx="0" iyy="0.0001" iyz="0" izx="0" izy="0" izz="0.001"/>
    </inertial>
  </link>
  <joint name="front_sensor_joint" type="fixed">
    <parent link="body"/>
    <child link="front_sensor"/>
    <origin rpy="0 0 1.57079632679" xyz="0.0325 0.04 0.03"/>
  </joint>
  <gazebo reference="front_sensor">
    <sensor name="front_light_sensor" type="ray">
      <pose>0 0 0 0 0 0</pose>
      <visualize>true</visualize>
      <update_rate>20</update_rate>
      <ray>
        <scan>
          <horizontal>
            <sapmles>10</sapmles>
            <resolution>1</resolution>
            <min_angle>0.09</min_angle>
            <max_angle>0.09</max_angle>
          </horizontal>
        </scan>
        <range>
          <min>0.01</min>
          <max>0.2</max>
          <resolution>0.001</resolution>
        </range>
        <noise>
          <type>gaussian</type>
          <mean>0.0</mean>
          <stdev>0.005</stdev>
        </noise>
      </ray>
      <plugin filename="libgazebo_ros_laser.so" name="gazebo_front_light_sensor_controller">
        <topicName>/light_sensor/front/scan</topicName>
        <frameName>front_sensor</frameName>
      </plugin>
    </sensor>
  </gazebo>
</robot>

